<?xml version="1.0" ?>
<!-- =================================================================================== -->
<!-- |    This document was autogenerated by xacro from kyon_leg.urdf.xacro            | -->
<!-- |    EDITING THIS FILE BY HAND IS NOT RECOMMENDED                                 | -->
<!-- =================================================================================== -->
<robot name="kyon">
  <!-- /macro legs -->
  <!-- scaling factor for available peack torque link side, from 0 to 1 -->
  <material name="black">
    <color rgba="0.4 0.4 0.4 1"/>
  </material>
  <material name="dark_grey">
    <color rgba="0.1 0.1 0.1 1"/>
  </material>
  <!-- Compound properties (i.e. based on the props parsed from the yaml) -->
  <!-- Compound properties (i.e. based on the props parsed from the yaml) -->
  <link name="world"/>
  <joint name="base_joint" type="fixed">
    <parent link="world"/>
    <child link="pelvis"/>
  </joint>
  <link name="pelvis"/>
  <!-- links -->
  <link name="hip_roll_2_link">
    <inertial>
      <origin xyz="0.0 0.0 0.0"/>
      <mass value="1.8"/>
      <inertia ixx="0.001893666666666667" ixy="0.0" ixz="0.0" iyy="0.001893666666666667" iyz="0.0" izz="0.002254000000000001"/>
    </inertial>
    <visual>
      <origin rpy="0.0 0.0 0.0" xyz="0.0 0.0 0.0"/>
      <geometry>
        <!-- <cylinder radius="${cylinder_radius}" length="${cylinder_length}"/> -->
        <mesh filename="package://kyon_urdf/meshes/mesh_hip-roll.stl" scale="0.001 0.001 0.001"/>
      </geometry>
      <material name="dark_grey"/>
    </visual>
    <collision>
      <origin rpy="0.0 0.0 0.0" xyz="0.0 0.0 0.0"/>
      <geometry>
        <!-- <cylinder radius="${cylinder_radius}" length="${cylinder_length}"/> -->
        <mesh filename="package://kyon_urdf/meshes/collision/mesh_hip-roll.stl" scale="0.001 0.001 0.001"/>
      </geometry>
    </collision>
  </link>
  <link name="hip_pitch_2_link">
    <inertial>
      <origin xyz="0.0 0.0 0.0"/>
      <mass value="1.8"/>
      <inertia ixx="0.001893666666666667" ixy="0.0" ixz="0.0" iyy="0.001893666666666667" iyz="0.0" izz="0.002254000000000001"/>
    </inertial>
    <visual>
      <origin rpy="0.0 0.0 0.0" xyz="0.0 0.0 0.0"/>
      <geometry>
        <mesh filename="package://kyon_urdf/meshes/mesh_hip-pitch.stl" scale="0.001 0.001 0.001"/>
      </geometry>
      <material name="dark_grey"/>
    </visual>
    <collision>
      <origin rpy="0.0 0.0 0.0" xyz="0.0 0.0 0.0"/>
      <geometry>
        <mesh filename="package://kyon_urdf/meshes/collision/mesh_hip-pitch.stl" scale="0.001 0.001 0.001"/>
      </geometry>
    </collision>
  </link>
  <!-- joints -->
  <joint name="hip_roll_2" type="fixed">
    <parent link="pelvis"/>
    <child link="hip_roll_2_link"/>
    <origin rpy="0.0 1.57079632679 0.0" xyz="0.40936 0.0775 0.0"/>
    <axis xyz="0 0 1"/>
    <limit effort="132" lower="-2.51" upper="2.03" velocity="15.5"/>
  </joint>
  <joint name="hip_pitch_2" type="revolute">
    <parent link="hip_roll_2_link"/>
    <child link="hip_pitch_2_link"/>
    <origin rpy="-1.57079632679 1.57079632679 0.0" xyz="0.0 0.05086 0.0"/>
    <axis xyz="0 0 1"/>
    <limit effort="132" lower="-2.3266" upper="2.3266" velocity="15.5"/>
  </joint>
  <link name="knee_pitch_2_link">
    <inertial>
      <origin xyz="0.0 0.0 0.0"/>
      <mass value="1.8"/>
      <inertia ixx="0.001893666666666667" ixy="0.0" ixz="0.0" iyy="0.001893666666666667" iyz="0.0" izz="0.002254000000000001"/>
    </inertial>
    <visual>
      <origin rpy="0.0 0.0 0.0" xyz="0.0 0.0 0.0"/>
      <geometry>
        <mesh filename="package://kyon_urdf/meshes/mesh_foot-leg.stl" scale="0.001 0.001 0.001"/>
      </geometry>
      <material name="dark_grey"/>
    </visual>
    <collision>
      <origin rpy="0.0 0.0 0.0" xyz="0.0 0.0 0.0"/>
      <geometry>
        <mesh filename="package://kyon_urdf/meshes/collision/mesh_foot-leg.stl" scale="0.001 0.001 0.001"/>
      </geometry>
    </collision>
  </link>
  <joint name="knee_pitch_2" type="revolute">
    <parent link="hip_pitch_2_link"/>
    <child link="knee_pitch_2_link"/>
    <origin rpy="0.0 0.0 0.0" xyz="0.0 -0.34600000000000003 0.16671000000000002"/>
    <axis xyz="0 0 1"/>
    <limit effort="132" lower="-3.3266" upper="3.3266" velocity="15.5"/>
  </joint>
  <link name="contact_2"/>
  <joint name="contact_2_joint" type="fixed">
    <parent link="knee_pitch_2_link"/>
    <child link="contact_2"/>
    <origin rpy="1.57 0 2.356" xyz="-0.03 -0.35 0.03"/>
  </joint>
  <link name="knee_pitch_2_link">
    <inertial>
      <origin xyz="0.0 0.0 0.0"/>
      <mass value="1.8"/>
      <inertia ixx="0.001893666666666667" ixy="0.0" ixz="0.0" iyy="0.001893666666666667" iyz="0.0" izz="0.002254000000000001"/>
    </inertial>
    <visual>
      <origin rpy="0.0 0.0 0.0" xyz="0.0 0.0 0.0"/>
      <geometry>
        <mesh filename="package://kyon_urdf/meshes/mesh_fixed-wheel-leg.stl" scale="0.001 0.001 0.001"/>
      </geometry>
      <material name="dark_grey"/>
    </visual>
    <collision>
      <origin rpy="0.0 0.0 0.0" xyz="0.0 0.0 0.0"/>
      <geometry>
        <mesh filename="package://kyon_urdf/meshes/collision/mesh_fixed-wheel-leg.stl" scale="0.001 0.001 0.001"/>
      </geometry>
    </collision>
  </link>
  <link name="wheel_2_link">
    <inertial>
      <origin xyz="0.0 0.0 0.0"/>
      <mass value="1.8"/>
      <inertia ixx="0.001893666666666667" ixy="0.0" ixz="0.0" iyy="0.001893666666666667" iyz="0.0" izz="0.002254000000000001"/>
    </inertial>
    <visual>
      <origin rpy="0.0 0.0 0.0" xyz="0.0 0.0 0.0"/>
      <geometry>
        <!-- <cylinder radius="${cylinder_radius}" length="${cylinder_length}"/> -->
        <mesh filename="package://kyon_urdf/meshes/mesh_wheel.stl" scale="0.001 0.001 0.001"/>
      </geometry>
      <material name="dark_grey"/>
    </visual>
    <collision>
      <origin rpy="0.0 0.0 0.0" xyz="0.0 0.0 0.0"/>
      <geometry>
        <!-- <cylinder radius="${cylinder_radius}" length="${cylinder_length}"/> -->
        <mesh filename="package://kyon_urdf/meshes/collision/mesh_wheel.stl" scale="0.001 0.001 0.001"/>
      </geometry>
    </collision>
  </link>
  <joint name="knee_pitch_2" type="revolute">
    <parent link="hip_pitch_2_link"/>
    <child link="knee_pitch_2_link"/>
    <origin rpy="0.0 0.0 0.0" xyz="0.0 -0.34600000000000003 0.16671000000000002"/>
    <axis xyz="0 0 1"/>
    <limit effort="132" lower="-3.3266" upper="3.3266" velocity="15.5"/>
  </joint>
  <joint name="wheel_joint_2" type="revolute">
    <parent link="knee_pitch_2"/>
    <child link="wheel_2_link"/>
    <origin rpy="0.0 0.0 0.0" xyz="0.0 -0.3 0.054"/>
    <axis xyz="0 0 1"/>
    <limit effort="132" lower="-3.3266" upper="3.3266" velocity="15.5"/>
  </joint>
</robot>
