<?xml version="1.0" ?>
<!-- =================================================================================== -->
<!-- |    This document was autogenerated by xacro from kyon.urdf.xacro                | -->
<!-- |    EDITING THIS FILE BY HAND IS NOT RECOMMENDED                                 | -->
<!-- =================================================================================== -->
<robot name="kyon">
  <!-- scaling factor for available peack torque link side, from 0 to 1 -->
  <material name="black">
    <color rgba="0.4 0.4 0.4 1"/>
  </material>
  <material name="dark_grey">
    <color rgba="0.1 0.1 0.1 1"/>
  </material>
  <!-- Compound properties (i.e. based on the props parsed from the yaml) -->
  <link name="base_link"/>
  <link name="pelvis">
    <inertial>
      <origin xyz="0.04972368 0.0022995169 0.058657543"/>
      <mass value="23.024083"/>
      <inertia ixx="0.25825843" ixy="-0.0015196886" ixz="-0.074270479" iyy="1.2128223" iyz="0.0039226759" izz="1.1693352"/>
    </inertial>
    <visual>
      <origin rpy="0.0 0.0 0.0" xyz="0.0 0 0.0"/>
      <geometry>
        <mesh filename="package://kyon_urdf/meshes/mesh_pelvis.stl" scale="0.001 0.001 0.001"/>
      </geometry>
    </visual>
    <collision>
      <origin rpy="0.0 0.0 0.0" xyz="0.0 0 0.0"/>
      <geometry>
        <mesh filename="package://kyon_urdf/meshes/collision/mesh_pelvis.stl" scale="0.001 0.001 0.001"/>
      </geometry>
    </collision>
  </link>
  <joint name="base_joint" type="fixed">
    <parent link="pelvis"/>
    <child link="base_link"/>
    <origin rpy="0 0 0" xyz="0 0 0"/>
  </joint>
  <link name="imu_link"/>
  <joint name="imu_joint" type="fixed">
    <parent link="pelvis"/>
    <child link="imu_link"/>
  </joint>
  <!-- /macro arms -->
  <!-- LINKS -->
  <!-- shoulder yaw -->
  <link name="shoulder_yaw_1_link">
    <inertial>
      <origin xyz="0.0 -0.00013492411000000002 0.040858984"/>
      <mass value="0.67826074"/>
      <inertia ixx="0.0025001498999999996" ixy="-6.3655528e-07" ixz="1.7271058999999999e-07" iyy="0.0019131558999999998" iyz="-6.5053652e-05" izz="0.0019311455"/>
    </inertial>
    <visual>
      <origin rpy="0.0 0.0 0.0" xyz="0.0 0.0 0.0"/>
      <geometry>
        <mesh filename="package://kyon_urdf/meshes/mesh_sh-yaw.stl" scale="0.001 0.001 0.001"/>
      </geometry>
      <material name="dark_grey"/>
    </visual>
    <collision>
      <origin rpy="0.0 0.0 0.0" xyz="0.0 0.0 0.0"/>
      <geometry>
        <mesh filename="package://kyon_urdf/meshes/collision/mesh_sh-yaw.stl" scale="0.001 0.001 0.001"/>
      </geometry>
    </collision>
  </link>
  <link name="shoulder_pitch_1_link">
    <inertial>
      <origin xyz="-8.821274800000001e-06 -0.14226587000000002 -0.0040603042"/>
      <mass value="2.6591536"/>
      <inertia ixx="0.059933923" ixy="0.00010630782" ixz="-8.1788344e-06" iyy="0.0032807638999999998" iyz="-0.001092533" izz="0.059801167999999995"/>
    </inertial>
    <visual>
      <geometry>
        <mesh filename="package://kyon_urdf/meshes/mesh_sh-pitch.stl" scale="0.001 0.001 0.001"/>
      </geometry>
      <material name="dark_grey"/>
    </visual>
    <collision>
      <geometry>
        <mesh filename="package://kyon_urdf/meshes/collision/mesh_sh-pitch.stl" scale="0.001 0.001 0.001"/>
      </geometry>
    </collision>
  </link>
  <link name="elbow_pitch_1_link">
    <inertial>
      <origin xyz="-0.00032761312 -0.16511035000000002 0.022799378000000002"/>
      <mass value="1.048477"/>
      <inertia ixx="0.01112601" ixy="1.7724864e-05" ixz="6.0670899e-06" iyy="0.00095730481" iyz="-0.0010167295" izz="0.011293245999999998"/>
    </inertial>
    <visual>
      <geometry>
        <mesh filename="package://kyon_urdf/meshes/mesh_elbow.stl" scale="0.001 0.001 0.001"/>
      </geometry>
    </visual>
    <collision>
      <geometry>
        <mesh filename="package://kyon_urdf/meshes/mesh_elbow.stl" scale="0.001 0.001 0.001"/>
      </geometry>
    </collision>
  </link>
  <link name="wrist_pitch_1_link">
    <inertial>
      <origin xyz="-0.00035889305999999997 -0.056046555 -0.010441123"/>
      <mass value="0.8276976"/>
      <inertia ixx="0.001897925" ixy="1.5812979999999998e-05" ixz="-8.8320155e-06" iyy="0.0007269340299999999" iyz="0.00044823507999999996" izz="0.0018533680999999998"/>
    </inertial>
    <visual>
      <origin rpy="0.0 0.0 0.0" xyz="0.0 0.0 0.0"/>
      <geometry>
        <mesh filename="package://kyon_urdf/meshes/mesh_wrist-pitch.stl" scale="0.001 0.001 0.001"/>
      </geometry>
      <material name="dark_grey"/>
    </visual>
    <collision>
      <origin rpy="0.0 0.0 0.0" xyz="0.0 0.0 0.0"/>
      <geometry>
        <mesh filename="package://kyon_urdf/meshes/collision/mesh_wrist-pitch.stl" scale="0.001 0.001 0.001"/>
      </geometry>
    </collision>
  </link>
  <link name="wrist_yaw_1_link">
    <inertial>
      <origin xyz="0.0 -1.8381848999999998e-05 -0.016592053"/>
      <mass value="0.11855953"/>
      <inertia ixx="7.048152500000001e-05" ixy="-1.3031027e-07" ixz="0.0" iyy="7.3847541e-05" iyz="-2.5372644999999998e-08" izz="0.00011802904"/>
    </inertial>
    <visual>
      <origin rpy="0.0 0.0 0.0" xyz="0.0 0.0 0.0"/>
      <geometry>
        <mesh filename="package://kyon_urdf/meshes/mesh_wrist-yaw.stl" scale="0.001 0.001 0.001"/>
      </geometry>
      <material name="dark_grey"/>
    </visual>
    <collision>
      <origin rpy="0.0 0.0 0.0" xyz="0.0 0.0 0.0"/>
      <geometry>
        <mesh filename="package://kyon_urdf/meshes/collision/mesh_wrist-yaw.stl" scale="0.001 0.001 0.001"/>
      </geometry>
    </collision>
  </link>
  <!-- /LINKS -->
  <!-- JOINTS -->
  <!-- shoulder yaw -->
  <joint name="shoulder_yaw_1" type="revolute">
    <parent link="pelvis"/>
    <child link="shoulder_yaw_1_link"/>
    <origin rpy="-0.3490656 0.0 0.0" xyz="0.28 0.0998258 0.203238"/>
    <axis xyz="0 0 1"/>
    <limit effort="146" lower="-3.312" upper="3.312" velocity="3.8"/>
  </joint>
  <!-- arm pitch 1 -->
  <joint name="shoulder_pitch_1" type="revolute">
    <parent link="shoulder_yaw_1_link"/>
    <child link="shoulder_pitch_1_link"/>
    <origin rpy="-1.57079632679 0.0 -3.14159265358" xyz="0.0 0.0 0.0735"/>
    <axis xyz="0 0 1"/>
    <limit effort="122" lower="-3" upper="3" velocity="4.6"/>
  </joint>
  <joint name="elbow_pitch_1" type="revolute">
    <parent link="shoulder_pitch_1_link"/>
    <child link="elbow_pitch_1_link"/>
    <origin rpy="0.0 0.0 0.0" xyz="0.0 -0.32 0.0"/>
    <axis xyz="0 0 1"/>
    <limit effort="122" lower="-3" upper="3" velocity="4.6"/>
  </joint>
  <joint name="wrist_pitch_1" type="revolute">
    <parent link="elbow_pitch_1_link"/>
    <child link="wrist_pitch_1_link"/>
    <origin rpy="0.0 0.0 0.0" xyz="0.0 -0.25 0.0"/>
    <axis xyz="0 0 1"/>
    <limit effort="25" lower="-2.4056" upper="2.4056" velocity="14"/>
  </joint>
  <joint name="wrist_yaw_1" type="revolute">
    <parent link="wrist_pitch_1_link"/>
    <child link="wrist_yaw_1_link"/>
    <origin rpy="1.57079632679 0.0 0.0" xyz="0.0 -0.134862 0.0"/>
    <axis xyz="0 0 1"/>
    <limit effort="25" lower="-2.4056" upper="2.4056" velocity="14"/>
  </joint>
  <link name="dagana_1_base">
    <inertial>
      <origin xyz="-0.004224466600000001 -0.0027238215 0.053670845"/>
      <mass value="0.96534359"/>
      <inertia ixx="0.0020957096" ixy="-6.455410899999999e-05" ixz="4.4955880999999996e-05" iyy="0.0021216529" iyz="0.00037094612999999995" izz="0.0011572224"/>
    </inertial>
    <visual>
      <origin rpy="0.0 0.0 0.0" xyz="0.0 0.0 0.0"/>
      <geometry>
        <mesh filename="package://kyon_urdf/meshes/mesh_dagana-base.stl" scale="0.001 0.001 0.001"/>
      </geometry>
      <material name="dark_grey"/>
    </visual>
    <collision>
      <origin rpy="0.0 0.0 0.0" xyz="0.0 0.0 0.0"/>
      <geometry>
        <mesh filename="package://kyon_urdf/meshes/collision/mesh_dagana-base.stl" scale="0.001 0.001 0.001"/>
      </geometry>
    </collision>
  </link>
  <link name="dagana_1_claw">
    <inertial>
      <origin xyz="-0.0516203 0.0080601187 -0.037212096"/>
      <mass value="0.25739835"/>
      <inertia ixx="0.00029169897" ixy="8.3015178e-06" ixz="1.3355847e-05" iyy="0.00073268589" iyz="-2.1083033000000003e-06" izz="0.00051112938"/>
    </inertial>
    <visual>
      <origin rpy="0.0 0.0 0.0" xyz="0.0 0.0 0.0"/>
      <geometry>
        <mesh filename="package://kyon_urdf/meshes/mesh_dagana-clamp.stl" scale="0.001 0.001 0.001"/>
      </geometry>
      <material name="dark_grey"/>
    </visual>
    <collision>
      <origin rpy="0.0 0.0 0.0" xyz="0.0 0.0 0.0"/>
      <geometry>
        <mesh filename="package://kyon_urdf/meshes/collision/mesh_dagana-clamp.stl" scale="0.001 0.001 0.001"/>
      </geometry>
    </collision>
  </link>
  <joint name="dagana_1_base_joint" type="fixed">
    <parent link="wrist_yaw_1_link"/>
    <child link="dagana_1_base"/>
    <origin rpy="0.0 0.0 0.0" xyz="0.0 0.0 0.0"/>
  </joint>
  <joint name="dagana_1_clamp_joint" type="revolute">
    <parent link="dagana_1_base"/>
    <child link="dagana_1_claw"/>
    <origin rpy="0.0 1.57079632679 0.0" xyz="0.0361625 0.016 0.044"/>
    <axis xyz="0 0 1"/>
    <limit effort="25" lower="-3.4056" upper="3.4056" velocity="14"/>
  </joint>
  <!-- LINKS -->
  <!-- shoulder yaw -->
  <link name="shoulder_yaw_2_link">
    <inertial>
      <origin xyz="0.0 -0.00013492411000000002 0.040858984"/>
      <mass value="0.67826074"/>
      <inertia ixx="0.0025001498999999996" ixy="-6.3655528e-07" ixz="1.7271058999999999e-07" iyy="0.0019131558999999998" iyz="-6.5053652e-05" izz="0.0019311455"/>
    </inertial>
    <visual>
      <origin rpy="0.0 0.0 0.0" xyz="0.0 0.0 0.0"/>
      <geometry>
        <mesh filename="package://kyon_urdf/meshes/mesh_sh-yaw.stl" scale="0.001 0.001 0.001"/>
      </geometry>
      <material name="dark_grey"/>
    </visual>
    <collision>
      <origin rpy="0.0 0.0 0.0" xyz="0.0 0.0 0.0"/>
      <geometry>
        <mesh filename="package://kyon_urdf/meshes/collision/mesh_sh-yaw.stl" scale="0.001 0.001 0.001"/>
      </geometry>
    </collision>
  </link>
  <link name="shoulder_pitch_2_link">
    <inertial>
      <origin xyz="-8.821274800000001e-06 -0.14226587000000002 -0.0040603042"/>
      <mass value="2.6591536"/>
      <inertia ixx="0.059933923" ixy="0.00010630782" ixz="-8.1788344e-06" iyy="0.0032807638999999998" iyz="-0.001092533" izz="0.059801167999999995"/>
    </inertial>
    <visual>
      <geometry>
        <mesh filename="package://kyon_urdf/meshes/mesh_sh-pitch.stl" scale="0.001 0.001 0.001"/>
      </geometry>
      <material name="dark_grey"/>
    </visual>
    <collision>
      <geometry>
        <mesh filename="package://kyon_urdf/meshes/collision/mesh_sh-pitch.stl" scale="0.001 0.001 0.001"/>
      </geometry>
    </collision>
  </link>
  <link name="elbow_pitch_2_link">
    <inertial>
      <origin xyz="-0.00032761312 -0.16511035000000002 0.022799378000000002"/>
      <mass value="1.048477"/>
      <inertia ixx="0.01112601" ixy="1.7724864e-05" ixz="6.0670899e-06" iyy="0.00095730481" iyz="-0.0010167295" izz="0.011293245999999998"/>
    </inertial>
    <visual>
      <geometry>
        <mesh filename="package://kyon_urdf/meshes/mesh_elbow.stl" scale="0.001 0.001 0.001"/>
      </geometry>
    </visual>
    <collision>
      <geometry>
        <mesh filename="package://kyon_urdf/meshes/mesh_elbow.stl" scale="0.001 0.001 0.001"/>
      </geometry>
    </collision>
  </link>
  <link name="wrist_pitch_2_link">
    <inertial>
      <origin xyz="-0.00035889305999999997 -0.056046555 -0.010441123"/>
      <mass value="0.8276976"/>
      <inertia ixx="0.001897925" ixy="1.5812979999999998e-05" ixz="-8.8320155e-06" iyy="0.0007269340299999999" iyz="0.00044823507999999996" izz="0.0018533680999999998"/>
    </inertial>
    <visual>
      <origin rpy="0.0 0.0 0.0" xyz="0.0 0.0 0.0"/>
      <geometry>
        <mesh filename="package://kyon_urdf/meshes/mesh_wrist-pitch.stl" scale="0.001 0.001 0.001"/>
      </geometry>
      <material name="dark_grey"/>
    </visual>
    <collision>
      <origin rpy="0.0 0.0 0.0" xyz="0.0 0.0 0.0"/>
      <geometry>
        <mesh filename="package://kyon_urdf/meshes/collision/mesh_wrist-pitch.stl" scale="0.001 0.001 0.001"/>
      </geometry>
    </collision>
  </link>
  <link name="wrist_yaw_2_link">
    <inertial>
      <origin xyz="0.0 -1.8381848999999998e-05 -0.016592053"/>
      <mass value="0.11855953"/>
      <inertia ixx="7.048152500000001e-05" ixy="-1.3031027e-07" ixz="0.0" iyy="7.3847541e-05" iyz="-2.5372644999999998e-08" izz="0.00011802904"/>
    </inertial>
    <visual>
      <origin rpy="0.0 0.0 0.0" xyz="0.0 0.0 0.0"/>
      <geometry>
        <mesh filename="package://kyon_urdf/meshes/mesh_wrist-yaw.stl" scale="0.001 0.001 0.001"/>
      </geometry>
      <material name="dark_grey"/>
    </visual>
    <collision>
      <origin rpy="0.0 0.0 0.0" xyz="0.0 0.0 0.0"/>
      <geometry>
        <mesh filename="package://kyon_urdf/meshes/collision/mesh_wrist-yaw.stl" scale="0.001 0.001 0.001"/>
      </geometry>
    </collision>
  </link>
  <!-- /LINKS -->
  <!-- JOINTS -->
  <!-- shoulder yaw -->
  <joint name="shoulder_yaw_2" type="revolute">
    <parent link="pelvis"/>
    <child link="shoulder_yaw_2_link"/>
    <origin rpy="0.3490656 0.0 0.0" xyz="0.28 -0.0998258 0.203238"/>
    <axis xyz="0 0 1"/>
    <limit effort="146" lower="-3.3458" upper="3.3458" velocity="3.8"/>
  </joint>
  <!-- arm pitch 1 -->
  <joint name="shoulder_pitch_2" type="revolute">
    <parent link="shoulder_yaw_2_link"/>
    <child link="shoulder_pitch_2_link"/>
    <origin rpy="-1.57079632679 0.0 0.0" xyz="0.0 0.0 0.0735"/>
    <axis xyz="0 0 1"/>
    <limit effort="122" lower="-3" upper="3" velocity="4.6"/>
  </joint>
  <joint name="elbow_pitch_2" type="revolute">
    <parent link="shoulder_pitch_2_link"/>
    <child link="elbow_pitch_2_link"/>
    <origin rpy="0.0 0.0 0.0" xyz="0.0 -0.32 0.0"/>
    <axis xyz="0 0 1"/>
    <limit effort="122" lower="-3" upper="3" velocity="4.6"/>
  </joint>
  <joint name="wrist_pitch_2" type="revolute">
    <parent link="elbow_pitch_2_link"/>
    <child link="wrist_pitch_2_link"/>
    <origin rpy="0.0 0.0 0.0" xyz="0.0 -0.25 0.0"/>
    <axis xyz="0 0 1"/>
    <limit effort="25" lower="-2.3266" upper="2.3266" velocity="14"/>
  </joint>
  <joint name="wrist_yaw_2" type="revolute">
    <parent link="wrist_pitch_2_link"/>
    <child link="wrist_yaw_2_link"/>
    <origin rpy="1.57079632679 0.0 0.0" xyz="0.0 -0.134862 0.0"/>
    <axis xyz="0 0 1"/>
    <limit effort="25" lower="-2.3266" upper="2.3266" velocity="14"/>
  </joint>
  <link name="dagana_2_base">
    <inertial>
      <origin xyz="-0.004224466600000001 -0.0027238215 0.053670845"/>
      <mass value="0.96534359"/>
      <inertia ixx="0.0020957096" ixy="-6.455410899999999e-05" ixz="4.4955880999999996e-05" iyy="0.0021216529" iyz="0.00037094612999999995" izz="0.0011572224"/>
    </inertial>
    <visual>
      <origin rpy="0.0 0.0 0.0" xyz="0.0 0.0 0.0"/>
      <geometry>
        <mesh filename="package://kyon_urdf/meshes/mesh_dagana-base.stl" scale="0.001 0.001 0.001"/>
      </geometry>
      <material name="dark_grey"/>
    </visual>
    <collision>
      <origin rpy="0.0 0.0 0.0" xyz="0.0 0.0 0.0"/>
      <geometry>
        <mesh filename="package://kyon_urdf/meshes/collision/mesh_dagana-base.stl" scale="0.001 0.001 0.001"/>
      </geometry>
    </collision>
  </link>
  <link name="dagana_2_claw">
    <inertial>
      <origin xyz="-0.0516203 0.0080601187 -0.037212096"/>
      <mass value="0.25739835"/>
      <inertia ixx="0.00029169897" ixy="8.3015178e-06" ixz="1.3355847e-05" iyy="0.00073268589" iyz="-2.1083033000000003e-06" izz="0.00051112938"/>
    </inertial>
    <visual>
      <origin rpy="0.0 0.0 0.0" xyz="0.0 0.0 0.0"/>
      <geometry>
        <mesh filename="package://kyon_urdf/meshes/mesh_dagana-clamp.stl" scale="0.001 0.001 0.001"/>
      </geometry>
      <material name="dark_grey"/>
    </visual>
    <collision>
      <origin rpy="0.0 0.0 0.0" xyz="0.0 0.0 0.0"/>
      <geometry>
        <mesh filename="package://kyon_urdf/meshes/collision/mesh_dagana-clamp.stl" scale="0.001 0.001 0.001"/>
      </geometry>
    </collision>
  </link>
  <joint name="dagana_2_base_joint" type="fixed">
    <parent link="wrist_yaw_2_link"/>
    <child link="dagana_2_base"/>
    <origin rpy="0.0 0.0 0.0" xyz="0.0 0.0 0.0"/>
  </joint>
  <joint name="dagana_2_clamp_joint" type="revolute">
    <parent link="dagana_2_base"/>
    <child link="dagana_2_claw"/>
    <origin rpy="0.0 1.57079632679 0.0" xyz="0.0361625 0.016 0.044"/>
    <axis xyz="0 0 1"/>
    <limit effort="25" lower="-3.3266" upper="3.3266" velocity="14"/>
  </joint>
  <!-- /macro legs -->
  <!-- links -->
  <link name="hip_roll_1_link">
    <inertial>
      <origin xyz="-0.00048748556 0.006340927 -0.11484611"/>
      <mass value="2.7479472"/>
      <inertia ixx="0.014719608" ixy="1.1262382e-05" ixz="3.2414002000000004e-05" iyy="0.014797972999999999" iyz="0.0017237369" izz="0.0049076886000000005"/>
    </inertial>
    <visual>
      <origin rpy="0.0 0.0 0.0" xyz="0.0 0.0 0.0"/>
      <geometry>
        <!-- <cylinder radius="${cylinder_radius}" length="${cylinder_length}"/> -->
        <mesh filename="package://kyon_urdf/meshes/mesh_hip-roll.stl" scale="0.001 -0.001 0.001"/>
      </geometry>
      <material name="dark_grey"/>
    </visual>
    <collision>
      <origin rpy="0.0 0.0 0.0" xyz="0.0 0.0 0.0"/>
      <geometry>
        <!-- <cylinder radius="${cylinder_radius}" length="${cylinder_length}"/> -->
        <mesh filename="package://kyon_urdf/meshes/collision/mesh_hip-roll.stl" scale="0.001 -0.001 0.001"/>
      </geometry>
    </collision>
  </link>
  <link name="hip_pitch_1_link">
    <inertial>
      <origin xyz="6.4486994e-05 -0.07812755900000001 0.14684759"/>
      <mass value="6.6449096"/>
      <inertia ixx="0.12473066999999999" ixy="-0.00067511845" ixz="-5.384152799999999e-05" iyy="0.034322669" iyz="0.028582838" izz="0.10356313"/>
    </inertial>
    <visual>
      <origin rpy="0.0 0.0 0.0" xyz="0.0 0.0 0.0"/>
      <geometry>
        <mesh filename="package://kyon_urdf/meshes/mesh_hip-pitch.stl" scale="0.001 0.001 0.001"/>
      </geometry>
      <material name="dark_grey"/>
    </visual>
    <collision>
      <origin rpy="0.0 0.0 0.0" xyz="0.0 0.0 0.0"/>
      <geometry>
        <mesh filename="package://kyon_urdf/meshes/collision/mesh_hip-pitch.stl" scale="0.001 0.001 0.001"/>
      </geometry>
    </collision>
  </link>
  <!-- joints -->
  <joint name="hip_roll_1" type="revolute">
    <parent link="pelvis"/>
    <child link="hip_roll_1_link"/>
    <origin rpy="0.0 1.57079632679 0.0" xyz="0.41100000000000003 0.0775 0.0"/>
    <axis xyz="0 0 1"/>
    <limit effort="185" lower="-2.03" upper="2.51" velocity="7.6"/>
  </joint>
  <joint name="hip_pitch_1" type="revolute">
    <parent link="hip_roll_1_link"/>
    <child link="hip_pitch_1_link"/>
    <origin rpy="0.0 1.57079632679 1.57079632679" xyz="0.0 -0.04746 0.0"/>
    <axis xyz="0 0 1"/>
    <limit effort="185" lower="-2.4056" upper="2.4056" velocity="7.6"/>
  </joint>
  <link name="knee_pitch_1_link">
    <inertial>
      <origin xyz="5.1193011000000004e-06 -0.10291594999999999 -0.0012895495"/>
      <mass value="0.70900216"/>
      <inertia ixx="0.012517512" ixy="5.4385779e-07" ixz="-1.4538899e-07" iyy="0.00080474409" iyz="0.001744629" izz="0.01230702"/>
    </inertial>
    <visual>
      <origin rpy="0.0 0.0 0.0" xyz="0.0 0.0 0.0"/>
      <geometry>
        <mesh filename="package://kyon_urdf/meshes/mesh_foot-leg.stl" scale="-0.001 0.001 0.001"/>
      </geometry>
      <material name="dark_grey"/>
    </visual>
    <collision>
      <origin rpy="0.0 0.0 0.0" xyz="0.0 0.0 0.0"/>
      <geometry>
        <mesh filename="package://kyon_urdf/meshes/collision/mesh_foot-leg.stl" scale="-0.001 0.001 0.001"/>
      </geometry>
    </collision>
  </link>
  <joint name="knee_pitch_1" type="revolute">
    <parent link="hip_pitch_1_link"/>
    <child link="knee_pitch_1_link"/>
    <origin rpy="0.0 0.0 0.0" xyz="0.0 -0.34600000000000003 0.24606"/>
    <axis xyz="0 0 1"/>
    <limit effort="185" lower="-3.4056" upper="3.4056" velocity="7.6"/>
  </joint>
  <link name="contact_1"/>
  <joint name="contact_1_joint" type="fixed">
    <parent link="knee_pitch_1_link"/>
    <child link="contact_1"/>
    <origin rpy="-1.57 0 0.785" xyz="0.03 -0.35 0.03"/>
  </joint>
  <!-- links -->
  <link name="hip_roll_2_link">
    <inertial>
      <origin xyz="-0.00048748556 0.006340927 -0.11484611"/>
      <mass value="2.7479472"/>
      <inertia ixx="0.014719608" ixy="-1.1262382e-05" ixz="3.2414002000000004e-05" iyy="0.014797972999999999" iyz="-0.0017237369" izz="0.0049076886000000005"/>
    </inertial>
    <visual>
      <origin rpy="0.0 0.0 0.0" xyz="0.0 0.0 0.0"/>
      <geometry>
        <!-- <cylinder radius="${cylinder_radius}" length="${cylinder_length}"/> -->
        <mesh filename="package://kyon_urdf/meshes/mesh_hip-roll.stl" scale="0.001 0.001 0.001"/>
      </geometry>
      <material name="dark_grey"/>
    </visual>
    <collision>
      <origin rpy="0.0 0.0 0.0" xyz="0.0 0.0 0.0"/>
      <geometry>
        <!-- <cylinder radius="${cylinder_radius}" length="${cylinder_length}"/> -->
        <mesh filename="package://kyon_urdf/meshes/collision/mesh_hip-roll.stl" scale="0.001 0.001 0.001"/>
      </geometry>
    </collision>
  </link>
  <link name="hip_pitch_2_link">
    <inertial>
      <origin xyz="6.4486994e-05 -0.07812755900000001 0.14684759"/>
      <mass value="6.6449096"/>
      <inertia ixx="0.12473066999999999" ixy="-0.00067511845" ixz="-5.384152799999999e-05" iyy="0.034322669" iyz="0.028582838" izz="0.10356313"/>
    </inertial>
    <visual>
      <origin rpy="0.0 0.0 0.0" xyz="0.0 0.0 0.0"/>
      <geometry>
        <mesh filename="package://kyon_urdf/meshes/mesh_hip-pitch.stl" scale="0.001 0.001 0.001"/>
      </geometry>
      <material name="dark_grey"/>
    </visual>
    <collision>
      <origin rpy="0.0 0.0 0.0" xyz="0.0 0.0 0.0"/>
      <geometry>
        <mesh filename="package://kyon_urdf/meshes/collision/mesh_hip-pitch.stl" scale="0.001 0.001 0.001"/>
      </geometry>
    </collision>
  </link>
  <!-- joints -->
  <joint name="hip_roll_2" type="revolute">
    <parent link="pelvis"/>
    <child link="hip_roll_2_link"/>
    <origin rpy="0.0 1.57079632679 0.0" xyz="0.41100000000000003 -0.0775 0.0"/>
    <axis xyz="0 0 1"/>
    <limit effort="185" lower="-2.51" upper="2.03" velocity="7.6"/>
  </joint>
  <joint name="hip_pitch_2" type="revolute">
    <parent link="hip_roll_2_link"/>
    <child link="hip_pitch_2_link"/>
    <origin rpy="0.0 -1.57079632679 1.57079632679" xyz="0.0 0.04746 0.0"/>
    <axis xyz="0 0 1"/>
    <limit effort="185" lower="-2.3266" upper="2.3266" velocity="7.6"/>
  </joint>
  <link name="knee_pitch_2_link">
    <inertial>
      <origin xyz="5.1193011000000004e-06 -0.10291594999999999 -0.0012895495"/>
      <mass value="0.70900216"/>
      <inertia ixx="0.012517512" ixy="-5.4385779e-07" ixz="1.4538899e-07" iyy="0.00080474409" iyz="0.001744629" izz="0.01230702"/>
    </inertial>
    <visual>
      <origin rpy="0.0 0.0 0.0" xyz="0.0 0.0 0.0"/>
      <geometry>
        <mesh filename="package://kyon_urdf/meshes/mesh_foot-leg.stl" scale="0.001 0.001 0.001"/>
      </geometry>
      <material name="dark_grey"/>
    </visual>
    <collision>
      <origin rpy="0.0 0.0 0.0" xyz="0.0 0.0 0.0"/>
      <geometry>
        <mesh filename="package://kyon_urdf/meshes/collision/mesh_foot-leg.stl" scale="0.001 0.001 0.001"/>
      </geometry>
    </collision>
  </link>
  <joint name="knee_pitch_2" type="revolute">
    <parent link="hip_pitch_2_link"/>
    <child link="knee_pitch_2_link"/>
    <origin rpy="0.0 0.0 0.0" xyz="0.0 -0.34600000000000003 0.24606"/>
    <axis xyz="0 0 1"/>
    <limit effort="185" lower="-3.3266" upper="3.3266" velocity="7.6"/>
  </joint>
  <link name="contact_2"/>
  <joint name="contact_2_joint" type="fixed">
    <parent link="knee_pitch_2_link"/>
    <child link="contact_2"/>
    <origin rpy="1.57 0 2.356" xyz="-0.03 -0.35 0.03"/>
  </joint>
  <!-- links -->
  <link name="hip_roll_3_link">
    <inertial>
      <origin xyz="-0.00048748556 0.006340927 -0.11484611"/>
      <mass value="2.7479472"/>
      <inertia ixx="0.014719608" ixy="1.1262382e-05" ixz="3.2414002000000004e-05" iyy="0.014797972999999999" iyz="0.0017237369" izz="0.0049076886000000005"/>
    </inertial>
    <visual>
      <origin rpy="0.0 0.0 0.0" xyz="0.0 0.0 0.0"/>
      <geometry>
        <!-- <cylinder radius="${cylinder_radius}" length="${cylinder_length}"/> -->
        <mesh filename="package://kyon_urdf/meshes/mesh_hip-roll.stl" scale="0.001 -0.001 0.001"/>
      </geometry>
      <material name="dark_grey"/>
    </visual>
    <collision>
      <origin rpy="0.0 0.0 0.0" xyz="0.0 0.0 0.0"/>
      <geometry>
        <!-- <cylinder radius="${cylinder_radius}" length="${cylinder_length}"/> -->
        <mesh filename="package://kyon_urdf/meshes/collision/mesh_hip-roll.stl" scale="0.001 -0.001 0.001"/>
      </geometry>
    </collision>
  </link>
  <link name="hip_pitch_3_link">
    <inertial>
      <origin xyz="6.4486994e-05 -0.07812755900000001 0.14684759"/>
      <mass value="6.6449096"/>
      <inertia ixx="0.12473066999999999" ixy="-0.00067511845" ixz="-5.384152799999999e-05" iyy="0.034322669" iyz="0.028582838" izz="0.10356313"/>
    </inertial>
    <visual>
      <origin rpy="0.0 0.0 0.0" xyz="0.0 0.0 0.0"/>
      <geometry>
        <mesh filename="package://kyon_urdf/meshes/mesh_hip-pitch.stl" scale="0.001 0.001 0.001"/>
      </geometry>
      <material name="dark_grey"/>
    </visual>
    <collision>
      <origin rpy="0.0 0.0 0.0" xyz="0.0 0.0 0.0"/>
      <geometry>
        <mesh filename="package://kyon_urdf/meshes/collision/mesh_hip-pitch.stl" scale="0.001 0.001 0.001"/>
      </geometry>
    </collision>
  </link>
  <!-- joints -->
  <joint name="hip_roll_3" type="revolute">
    <parent link="pelvis"/>
    <child link="hip_roll_3_link"/>
    <origin rpy="0.0 -1.57079632679 0.0" xyz="-0.41100000000000003 0.0775 0.0"/>
    <axis xyz="0 0 1"/>
    <limit effort="185" lower="-2.51" upper="2.03" velocity="7.6"/>
  </joint>
  <joint name="hip_pitch_3" type="revolute">
    <parent link="hip_roll_3_link"/>
    <child link="hip_pitch_3_link"/>
    <origin rpy="0.0 -1.57079632679 -1.57079632679" xyz="0.0 -0.04746 0.0"/>
    <axis xyz="0 0 1"/>
    <limit effort="185" lower="-2.4696" upper="2.4696" velocity="7.6"/>
  </joint>
  <link name="knee_pitch_3_link">
    <inertial>
      <origin xyz="5.1193011000000004e-06 -0.10291594999999999 -0.0012895495"/>
      <mass value="0.70900216"/>
      <inertia ixx="0.012517512" ixy="5.4385779e-07" ixz="-1.4538899e-07" iyy="0.00080474409" iyz="0.001744629" izz="0.01230702"/>
    </inertial>
    <visual>
      <origin rpy="0.0 0.0 0.0" xyz="0.0 0.0 0.0"/>
      <geometry>
        <mesh filename="package://kyon_urdf/meshes/mesh_foot-leg.stl" scale="-0.001 0.001 0.001"/>
      </geometry>
      <material name="dark_grey"/>
    </visual>
    <collision>
      <origin rpy="0.0 0.0 0.0" xyz="0.0 0.0 0.0"/>
      <geometry>
        <mesh filename="package://kyon_urdf/meshes/collision/mesh_foot-leg.stl" scale="-0.001 0.001 0.001"/>
      </geometry>
    </collision>
  </link>
  <joint name="knee_pitch_3" type="revolute">
    <parent link="hip_pitch_3_link"/>
    <child link="knee_pitch_3_link"/>
    <origin rpy="0.0 0.0 0.0" xyz="0.0 -0.34600000000000003 0.24606"/>
    <axis xyz="0 0 1"/>
    <limit effort="185" lower="-3.4696" upper="3.4696" velocity="7.6"/>
  </joint>
  <link name="contact_3"/>
  <joint name="contact_3_joint" type="fixed">
    <parent link="knee_pitch_3_link"/>
    <child link="contact_3"/>
    <origin rpy="-1.57 0 0.785" xyz="0.03 -0.35 0.03"/>
  </joint>
  <!-- links -->
  <link name="hip_roll_4_link">
    <inertial>
      <origin xyz="-0.00048748556 0.006340927 -0.11484611"/>
      <mass value="2.7479472"/>
      <inertia ixx="0.014719608" ixy="-1.1262382e-05" ixz="3.2414002000000004e-05" iyy="0.014797972999999999" iyz="-0.0017237369" izz="0.0049076886000000005"/>
    </inertial>
    <visual>
      <origin rpy="0.0 0.0 0.0" xyz="0.0 0.0 0.0"/>
      <geometry>
        <!-- <cylinder radius="${cylinder_radius}" length="${cylinder_length}"/> -->
        <mesh filename="package://kyon_urdf/meshes/mesh_hip-roll.stl" scale="0.001 0.001 0.001"/>
      </geometry>
      <material name="dark_grey"/>
    </visual>
    <collision>
      <origin rpy="0.0 0.0 0.0" xyz="0.0 0.0 0.0"/>
      <geometry>
        <!-- <cylinder radius="${cylinder_radius}" length="${cylinder_length}"/> -->
        <mesh filename="package://kyon_urdf/meshes/collision/mesh_hip-roll.stl" scale="0.001 0.001 0.001"/>
      </geometry>
    </collision>
  </link>
  <link name="hip_pitch_4_link">
    <inertial>
      <origin xyz="6.4486994e-05 -0.07812755900000001 0.14684759"/>
      <mass value="6.6449096"/>
      <inertia ixx="0.12473066999999999" ixy="-0.00067511845" ixz="-5.384152799999999e-05" iyy="0.034322669" iyz="0.028582838" izz="0.10356313"/>
    </inertial>
    <visual>
      <origin rpy="0.0 0.0 0.0" xyz="0.0 0.0 0.0"/>
      <geometry>
        <mesh filename="package://kyon_urdf/meshes/mesh_hip-pitch.stl" scale="0.001 0.001 0.001"/>
      </geometry>
      <material name="dark_grey"/>
    </visual>
    <collision>
      <origin rpy="0.0 0.0 0.0" xyz="0.0 0.0 0.0"/>
      <geometry>
        <mesh filename="package://kyon_urdf/meshes/collision/mesh_hip-pitch.stl" scale="0.001 0.001 0.001"/>
      </geometry>
    </collision>
  </link>
  <!-- joints -->
  <joint name="hip_roll_4" type="revolute">
    <parent link="pelvis"/>
    <child link="hip_roll_4_link"/>
    <origin rpy="0.0 -1.57079632679 0.0" xyz="-0.41100000000000003 -0.0775 0.0"/>
    <axis xyz="0 0 1"/>
    <limit effort="185" lower="-2.03" upper="2.51" velocity="7.6"/>
  </joint>
  <joint name="hip_pitch_4" type="revolute">
    <parent link="hip_roll_4_link"/>
    <child link="hip_pitch_4_link"/>
    <origin rpy="0.0 1.57079632679 -1.57079632679" xyz="0.0 0.04746 0.0"/>
    <axis xyz="0 0 1"/>
    <limit effort="185" lower="-2.3426" upper="2.3426" velocity="7.6"/>
  </joint>
  <link name="knee_pitch_4_link">
    <inertial>
      <origin xyz="5.1193011000000004e-06 -0.10291594999999999 -0.0012895495"/>
      <mass value="0.70900216"/>
      <inertia ixx="0.012517512" ixy="-5.4385779e-07" ixz="1.4538899e-07" iyy="0.00080474409" iyz="0.001744629" izz="0.01230702"/>
    </inertial>
    <visual>
      <origin rpy="0.0 0.0 0.0" xyz="0.0 0.0 0.0"/>
      <geometry>
        <mesh filename="package://kyon_urdf/meshes/mesh_foot-leg.stl" scale="0.001 0.001 0.001"/>
      </geometry>
      <material name="dark_grey"/>
    </visual>
    <collision>
      <origin rpy="0.0 0.0 0.0" xyz="0.0 0.0 0.0"/>
      <geometry>
        <mesh filename="package://kyon_urdf/meshes/collision/mesh_foot-leg.stl" scale="0.001 0.001 0.001"/>
      </geometry>
    </collision>
  </link>
  <joint name="knee_pitch_4" type="revolute">
    <parent link="hip_pitch_4_link"/>
    <child link="knee_pitch_4_link"/>
    <origin rpy="0.0 0.0 0.0" xyz="0.0 -0.34600000000000003 0.24606"/>
    <axis xyz="0 0 1"/>
    <limit effort="185" lower="-3.3426" upper="3.3426" velocity="7.6"/>
  </joint>
  <link name="contact_4"/>
  <joint name="contact_4_joint" type="fixed">
    <parent link="knee_pitch_4_link"/>
    <child link="contact_4"/>
    <origin rpy="1.57 0 2.356" xyz="-0.03 -0.35 0.03"/>
  </joint>
  <!-- ************ Control frames ************ -->
  <!--xacro:include filename="$(find pholus_urdf)/urdf/control_frames.urdf.xacro"/-->
  <link name="world"/>
  <joint name="reference" type="floating">
    <parent link="world"/>
    <child link="pelvis"/>
  </joint>
</robot>
