<?xml version="1.0"?>
<robot xmlns:xacro="http://ros.org/wiki/xacro">

<!-- macro legs -->
<xacro:macro name="foot_leg" params="leg_num parent origin_x origin_y mirror">

<link name="knee_pitch_${leg_num}_link">
    <inertial>
        <origin xyz="${KneePitch_x} ${KneePitch_y} ${KneePitch_z}"/>
        <mass value="${KneePitch_mass}"/>
        <inertia ixx="${KneePitch_xx}" ixy="${mirror*KneePitch_xy}" ixz="${mirror*KneePitch_xz}" iyy="${KneePitch_yy}" iyz="${KneePitch_yz}" izz="${KneePitch_zz}"/>
    </inertial>
    <visual>
        <origin xyz="0.0 0.0 0.0"  rpy="0.0 0.0 0.0"/>
        <geometry>
            <mesh filename="package://kyon_urdf/meshes/mesh_foot-leg.stl" scale="${mirror*0.001} 0.001 0.001"/>
        </geometry>
        <material name="dark_grey"/>
    </visual>
    <collision>
        <origin xyz="0.0 0.0 0.0"  rpy="0.0 0.0 0.0"/>
        <geometry>
            <mesh filename="package://kyon_urdf/meshes/collision/mesh_foot-leg.stl" scale="${mirror*0.001} 0.001 0.001"/>
        </geometry>
    </collision>
</link>

<joint name="knee_pitch_${leg_num}" type="revolute">
    <parent link="${parent}"/>
    <child link="knee_pitch_${leg_num}_link"/>
    <origin xyz="${KneePitch_Ox} ${KneePitch_Oy} ${KneePitch_Oz}" rpy="${KneePitch_roll} ${KneePitch_pitch} ${KneePitch_yaw}"/>
    <axis xyz="0 0 1"/>
    <limit lower="${knee_pitch_lower[leg_num-1]}" upper="${knee_pitch_upper[leg_num-1]}" effort="${motorA_effort}" velocity="${motorA_velocity}"/> 
</joint>

<link name="contact_${leg_num}"/>
<joint name="contact_${leg_num}_joint" type="fixed">
    <parent link="knee_pitch_${leg_num}_link"/>
    <child link="contact_${leg_num}"/>
    <origin xyz="${-mirror*0.0} -0.3 0.054" rpy="${1.57*mirror} ${0} ${0.785 if mirror == -1 else 2.356}"/>    
</joint>

</xacro:macro>
</robot>
