<?xml version="1.0"?>
<robot xmlns:xacro="http://ros.org/wiki/xacro">

<!-- macro legs -->
<xacro:macro name="kyon_dagana" params="arm_num parent">

<link name="dagana_${arm_num}_base">
    <inertial>
        <origin xyz="${Dagana_x} ${Dagana_y} ${Dagana_z}"/>
        <mass value="${Dagana_mass}"/>
        <inertia ixx="${Dagana_xx}" ixy="${Dagana_xy}" ixz="${Dagana_xz}" iyy="${Dagana_yy}" iyz="${Dagana_yz}" izz="${Dagana_zz}"/>
    </inertial>
    <visual>
        <origin xyz="0.0 0.0 0.0"  rpy="0.0 0.0 0.0"/>
        <geometry>
            <mesh filename="package://kyon_urdf/meshes/mesh_dagana-base.stl" scale="0.001 0.001 0.001"/>
        </geometry>
        <material name="dark_grey"/>
    </visual>
    <collision>
        <origin xyz="0.0 0.0 0.0"  rpy="0.0 0.0 0.0"/>
        <geometry>
            <mesh filename="package://kyon_urdf/meshes/collision/mesh_dagana-base.stl" scale="0.001 0.001 0.001"/>
        </geometry>
    </collision>
</link>

<link name="dagana_${arm_num}_claw">
    <inertial>
        <origin xyz="${DaganaClaw_x} ${DaganaClaw_y} ${DaganaClaw_z}"/>
        <mass value="${DaganaClaw_mass}"/>
        <inertia ixx="${DaganaClaw_xx}" ixy="${DaganaClaw_xy}" ixz="${DaganaClaw_xz}" iyy="${DaganaClaw_yy}" iyz="${DaganaClaw_yz}" izz="${DaganaClaw_zz}"/>
    </inertial>
    <visual>
        <origin xyz="0.0 0.0 0.0"  rpy="0.0 0.0 0.0"/>
        <geometry>
            <mesh filename="package://kyon_urdf/meshes/mesh_dagana-clamp.stl" scale="0.001 0.001 0.001"/>
        </geometry>
        <material name="dark_grey"/>
    </visual>
    <collision>
        <origin xyz="0.0 0.0 0.0"  rpy="0.0 0.0 0.0"/>
        <geometry>
            <mesh filename="package://kyon_urdf/meshes/collision/mesh_dagana-clamp.stl" scale="0.001 0.001 0.001"/>
        </geometry>
    </collision>
</link>

<joint name="dagana_${arm_num}_base_joint" type="fixed">
    <parent link="${parent}"/>
    <child link="dagana_${arm_num}_base"/>
    <origin xyz="${DaganaBase_Ox} ${DaganaBase_Oy} ${DaganaBase_Oz}" rpy="${DaganaBase_roll} ${DaganaBase_pitch} ${DaganaBase_yaw}"/>
</joint>

<joint name="dagana_${arm_num}_clamp_joint" type="revolute">
    <parent link="dagana_${arm_num}_base"/>
    <child link="dagana_${arm_num}_claw"/>
    <origin xyz="${DaganaClamp_Ox} ${DaganaClamp_Oy} ${DaganaClamp_Oz}" rpy="${DaganaClamp_roll} ${DaganaClamp_pitch} ${DaganaClamp_yaw}"/>
    <axis xyz="0 0 1"/>
    <limit lower="${dagana_lower[arm_num-1]}" upper="${dagana_upper[arm_num-1]}" effort="${motorD_effort}" velocity="${motorD_velocity}"/> 
</joint>

</xacro:macro>
</robot>