<?xml version="1.0"?>
<robot xmlns:xacro="http://ros.org/wiki/xacro">

<xacro:include filename="$(find kyon_urdf)/urdf/parts/kyon_dagana.urdf.xacro"/>

<!-- macro arms -->
<xacro:macro name="kyon_arm" params="arm_num rot parent">
	
<!-- LINKS -->
<!-- shoulder yaw -->
<link name="shoulder_yaw_${arm_num}_link">
	<inertial>
		<origin xyz="${ShoulderYaw_x} ${ShoulderYaw_y} ${ShoulderYaw_z}"/>
		<mass value="${ShoulderYaw_mass}"/>   
		<inertia ixx="${ShoulderYaw_xx}" ixy="${ShoulderYaw_xy}" ixz="${ShoulderYaw_xz}" iyy="${ShoulderYaw_yy}" iyz="${ShoulderYaw_yz}" izz="${ShoulderYaw_zz}"/>
	</inertial>
	<visual>
		<origin xyz="0.0 0.0 0.0"  rpy="0.0 0.0 0.0"/>
		<geometry>
			<mesh filename="package://kyon_urdf/meshes/mesh_sh-yaw.stl" scale="0.001 0.001 0.001"/>
		</geometry>
		<material name="dark_grey"/>
	</visual>
	<collision>
		<origin xyz="0.0 0.0 0.0"  rpy="0.0 0.0 0.0"/>
		<geometry>
			<mesh filename="package://kyon_urdf/meshes/collision/mesh_sh-yaw.stl" scale="0.001 0.001 0.001"/>
		</geometry>
	</collision>
</link>

<link name="shoulder_pitch_${arm_num}_link">
	<inertial>
		<origin xyz="${ShoulderPitch_x} ${ShoulderPitch_y} ${ShoulderPitch_z}"/>
		<mass value="${ShoulderPitch_mass}"/>
		<inertia ixx="${ShoulderPitch_xx}" ixy="${ShoulderPitch_xy}" ixz="${ShoulderPitch_xz}" iyy="${ShoulderPitch_yy}" iyz="${ShoulderPitch_yz}" izz="${ShoulderPitch_zz}"/>
	</inertial>
	<visual>
	  	<geometry>
	 		<mesh filename="package://kyon_urdf/meshes/mesh_sh-pitch.stl" scale="0.001 0.001 0.001"/>
	  	</geometry>
  		<material name="dark_grey"/>
	</visual>
	<collision>
	  	<geometry>
			<mesh filename="package://kyon_urdf/meshes/collision/mesh_sh-pitch.stl" scale="0.001 0.001 0.001"/>
		</geometry>
	</collision>
</link>

<link name="elbow_pitch_${arm_num}_link">
	<inertial>
		<origin xyz="${ElbowPitch_x} ${ElbowPitch_y} ${ElbowPitch_z}"/>	
		<mass value="${ElbowPitch_mass}"/>
		<inertia ixx="${ElbowPitch_xx}" ixy="${ElbowPitch_xy}" ixz="${ElbowPitch_xz}" iyy="${ElbowPitch_yy}" iyz="${ElbowPitch_yz}" izz="${ElbowPitch_zz}"/>
	</inertial>
	<visual>
		<geometry>
			<mesh filename="package://kyon_urdf/meshes/mesh_elbow.stl" scale="0.001 0.001 0.001"/>
		</geometry>
	</visual>
	<collision>
		<geometry>
			<mesh filename="package://kyon_urdf/meshes/mesh_elbow.stl" scale="0.001 0.001 0.001"/>
		</geometry>
	</collision>
</link>

<link name="wrist_pitch_${arm_num}_link">
	<inertial>
		<origin xyz="${WristPitch_x} ${WristPitch_y} ${WristPitch_z}"/>
		<mass value="${WristPitch_mass}"/>
		<inertia ixx="${WristPitch_xx}" ixy="${WristPitch_xy}" ixz="${WristPitch_xz}" iyy="${WristPitch_yy}" iyz="${WristPitch_yz}" izz="${WristPitch_zz}"/>
	</inertial>
	<visual>
		<origin xyz="0.0 0.0 0.0"  rpy="0.0 0.0 0.0"/>
	  	<geometry>
	 		<mesh filename="package://kyon_urdf/meshes/mesh_wrist-pitch.stl" scale="0.001 0.001 0.001"/>
	  	</geometry>
  		<material name="dark_grey"/>
	</visual>
	<collision>
		<origin xyz="0.0 0.0 0.0"  rpy="0.0 0.0 0.0"/>
		<geometry>
			<mesh filename="package://kyon_urdf/meshes/collision/mesh_wrist-pitch.stl" scale="0.001 0.001 0.001"/>
		</geometry>
	</collision>
</link>

<link name="wrist_yaw_${arm_num}_link">
	<inertial>
		<origin xyz="${WristYaw_x} ${WristYaw_y} ${WristYaw_z}"/>
		<mass value="${WristYaw_mass}"/>
		<inertia ixx="${WristYaw_xx}" ixy="${WristYaw_xy}" ixz="${WristYaw_xz}" iyy="${WristYaw_yy}" iyz="${WristYaw_yz}" izz="${WristYaw_zz}"/>
	</inertial>
	<visual>
		<origin xyz="0.0 0.0 0.0"  rpy="0.0 0.0 0.0"/>
	  	<geometry>
	 		<mesh filename="package://kyon_urdf/meshes/mesh_wrist-yaw.stl" scale="0.001 0.001 0.001"/>
	  	</geometry>
  		<material name="dark_grey"/>
	</visual>
	<collision>
		<origin xyz="0.0 0.0 0.0"  rpy="0.0 0.0 0.0"/>
		<geometry>
			<mesh filename="package://kyon_urdf/meshes/collision/mesh_wrist-yaw.stl" scale="0.001 0.001 0.001"/>
		</geometry>
	</collision>
</link>

<!-- /LINKS -->

<!-- JOINTS -->
<!-- shoulder yaw -->
<joint name="shoulder_yaw_${arm_num}" type="revolute">
	<parent link="${parent}"/>
	<child link="shoulder_yaw_${arm_num}_link"/>
	<origin xyz="${ShoulderYaw_Ox} ${rot * ShoulderYaw_Oy} ${ShoulderYaw_Oz}" rpy="${rot * ShoulderYaw_roll} ${ShoulderYaw_pitch} ${ShoulderYaw_yaw}"/>
	<axis xyz="0 0 1"/>
	<limit lower="${j_shoulder_yaw_lower[arm_num-1]}" upper="${j_shoulder_yaw_upper[arm_num-1]}" effort="${motorB_effort}" velocity="${motorB_velocity}"/>
</joint>

<!-- arm pitch 1 -->
<joint name="shoulder_pitch_${arm_num}" type="revolute">
	<parent link="shoulder_yaw_${arm_num}_link"/>
	<child link="shoulder_pitch_${arm_num}_link"/>
	<origin xyz="${ShoulderPitch_Ox} ${ShoulderPitch_Oy} ${ShoulderPitch_Oz}" rpy="${ShoulderPitch_roll} ${ShoulderPitch_pitch} ${ShoulderPitch_yaw + rot * PI_2}"/>
	<axis xyz="0 0 1"/>
	<limit lower="${j_pitch_1_lower[arm_num-1]}" upper="${j_pitch_1_upper[arm_num-1]}" effort="${motorC_effort}" velocity="${motorC_velocity}"/>
</joint>

<joint name="elbow_pitch_${arm_num}" type="revolute">
	<parent link="shoulder_pitch_${arm_num}_link"/>
	<child link="elbow_pitch_${arm_num}_link"/>
	<origin xyz="${ElbowPitch_Ox} ${ElbowPitch_Oy} ${ElbowPitch_Oz}" rpy="${ElbowPitch_roll} ${ElbowPitch_pitch} ${ElbowPitch_yaw}"/>
	<axis xyz="0 0 1"/>
	<limit lower="${j_pitch_1_lower[arm_num-1]}" upper="${j_pitch_1_upper[arm_num-1]}" effort="${motorC_effort}" velocity="${motorC_velocity}"/>
</joint>

<joint name="wrist_pitch_${arm_num}" type="revolute">
	<parent link="elbow_pitch_${arm_num}_link"/>
	<child link="wrist_pitch_${arm_num}_link"/>
	<origin xyz="${WristPitch_Ox} ${WristPitch_Oy} ${WristPitch_Oz}" rpy="${WristPitch_roll} ${WristPitch_pitch} ${WristPitch_yaw}"/>
	<axis xyz="0 0 1"/>
	<limit lower="${j_pitch_2_lower[arm_num-1]}" upper="${j_pitch_2_upper[arm_num-1]}" effort="${motorD_effort}" velocity="${motorD_velocity}"/>
</joint>
	
<joint name="wrist_yaw_${arm_num}" type="revolute">
	<parent link="wrist_pitch_${arm_num}_link"/>
	<child link="wrist_yaw_${arm_num}_link"/>
	<origin xyz="${WristYaw_Ox} ${WristYaw_Oy} ${WristYaw_Oz}" rpy="${WristYaw_roll} ${WristYaw_pitch} ${WristYaw_yaw}"/>
	<axis xyz="0 0 1"/>
	<limit lower="${j_pitch_2_lower[arm_num-1]}" upper="${j_pitch_2_upper[arm_num-1]}" effort="${motorD_effort}" velocity="${motorD_velocity}"/>
</joint>

<xacro:kyon_dagana arm_num="${arm_num}" parent="wrist_yaw_${arm_num}_link"/>

</xacro:macro>
<!-- /macro arms -->

</robot>
