<?xml version="1.0"?>
<robot xmlns:xacro="http://ros.org/wiki/xacro">

<!-- macro legs -->
<xacro:macro name="steering_wheel" params="leg_num parent origin_x origin_y mirror">

<link name="knee_pitch_${leg_num}_link">
    <inertial>
		<origin xyz="${KneePitchSteeringWheel_x} ${KneePitchSteeringWheel_y} ${KneePitchSteeringWheel_z}"/>
		<mass value="${KneePitchSteeringWheel_mass}"/>
		<inertia ixx="${KneePitchSteeringWheel_xx}" ixy="${KneePitchSteeringWheel_xy}" ixz="${KneePitchSteeringWheel_xz}" iyy="${KneePitchSteeringWheel_yy}" iyz="${KneePitchSteeringWheel_yz}" izz="${KneePitchSteeringWheel_zz}"/>
	</inertial>
	<visual>
		<origin xyz="0.0 0.0 0.0"  rpy="0.0 0.0 0.0"/>
	  	<geometry>
	 		<!-- <cylinder radius="${cylinder_radius}" length="${cylinder_length}"/> -->
			<mesh filename="package://kyon_urdf/meshes/mesh_knee-steering.stl" scale="0.001 0.001 0.001"/>
		</geometry> 
  		<material name="dark_grey"/>
	</visual>
	<collision>
		<origin xyz="0.0 0.0 0.0"  rpy="0.0 0.0 0.0"/>
		<geometry>
	 		<!-- <cylinder radius="${cylinder_radius}" length="${cylinder_length}"/> -->
			<mesh filename="package://kyon_urdf/meshes/collision/mesh_knee-steering.stl" scale="0.001 0.001 0.001"/>
		</geometry> 
	</collision>
</link>

<link name="ankle_yaw_${leg_num}_link">
    <inertial>
		<origin xyz="${AnkleYaw_x} ${AnkleYaw_y} ${AnkleYaw_z}"/>
		<mass value="${AnkleYaw_mass}"/>
		<inertia ixx="${AnkleYaw_xx}" ixy="${AnkleYaw_xy}" ixz="${AnkleYaw_xz}" iyy="${AnkleYaw_yy}" iyz="${AnkleYaw_yz}" izz="${AnkleYaw_zz}"/>
	</inertial>
	<visual>
		<origin xyz="0.0 0.0 0.0"  rpy="0.0 0.0 0.0"/>
	  	<geometry>
	 		<!-- <cylinder radius="${cylinder_radius}" length="${cylinder_length}"/> -->
			<mesh filename="package://kyon_urdf/meshes/mesh_ankle-yaw.stl" scale="0.001 0.001 0.001"/>
		</geometry> 
  		<material name="dark_grey"/>
	</visual>
	<collision>
		<origin xyz="0.0 0.0 0.0"  rpy="0.0 0.0 0.0"/>
		<geometry>
	 		<!-- <cylinder radius="${cylinder_radius}" length="${cylinder_length}"/> -->
			<mesh filename="package://kyon_urdf/meshes/collision/mesh_ankle-yaw.stl" scale="0.001 0.001 0.001"/>
		</geometry> 
	</collision>
</link>

<link name="wheel_${leg_num}_link">
    <inertial>
		<origin xyz="${SteeringWheel_x} ${SteeringWheel_y} ${SteeringWheel_z}"/>
		<mass value="${SteeringWheel_mass}"/>
		<inertia ixx="${SteeringWheel_xx}" ixy="${SteeringWheel_xy}" ixz="${SteeringWheel_xz}" iyy="${SteeringWheel_yy}" iyz="${SteeringWheel_yz}" izz="${SteeringWheel_zz}"/>
	</inertial>
	<visual>
		<origin xyz="0.0 0.0 0.0"  rpy="0.0 0.0 0.0"/>
	  	<geometry>
	 		<!-- <cylinder radius="${cylinder_radius}" length="${cylinder_length}"/> -->
			<mesh filename="package://kyon_urdf/meshes/mesh_wheel.stl" scale="0.001 0.001 0.001"/>
		</geometry> 
  		<material name="dark_grey"/>
	</visual>
	<collision>
		<origin xyz="0.0 0.0 0.0"  rpy="0.0 0.0 0.0"/>
		<geometry>
	 		<!-- <cylinder radius="${cylinder_radius}" length="${cylinder_length}"/> -->
			<mesh filename="package://kyon_urdf/meshes/collision/mesh_wheel.stl" scale="0.001 0.001 0.001"/>
		</geometry> 
	</collision>
</link>

<joint name="knee_pitch_${leg_num}" type="revolute">
    <parent link="${parent}"/>
    <child link="knee_pitch_${leg_num}_link"/>
    <origin xyz="${KneePitch_Ox} ${KneePitch_Oy} ${KneePitch_Oz}" rpy="${KneePitch_roll} ${KneePitch_pitch} ${KneePitch_yaw}"/>
    <axis xyz="0 0 1"/>
    <limit lower="${knee_pitch_lower[leg_num-1]}" upper="${knee_pitch_upper[leg_num-1]}" effort="${motorA_effort}" velocity="${motorA_velocity}"/> 
</joint>

<joint name="ankle_yaw_${leg_num}" type="revolute">
    <parent link="knee_pitch_${leg_num}_link"/>
    <child link="ankle_yaw_${leg_num}_link"/>
    <origin xyz="${AnkleYaw_Ox} ${AnkleYaw_Oy} ${AnkleYaw_Oz}" rpy="${AnkleYaw_roll} ${AnkleYaw_pitch} ${AnkleYaw_yaw}"/>
    <axis xyz="0 0 1"/>
    <limit lower="${knee_pitch_lower[leg_num-1]}" upper="${knee_pitch_upper[leg_num-1]}" effort="${motorA_effort}" velocity="${motorA_velocity}"/> 
</joint>

<joint name="wheel_joint_${leg_num}" type="revolute">
    <parent link="ankle_yaw_${leg_num}_link"/>
    <child link="wheel_${leg_num}_link"/>
    <origin xyz="${SteeringWheel_Ox} ${SteeringWheel_Oy} ${SteeringWheel_Oz}" rpy="${SteeringWheel_roll} ${SteeringWheel_pitch} ${SteeringWheel_yaw}"/>
    <axis xyz="0 0 1"/>
    <limit lower="${knee_pitch_lower[leg_num-1]}" upper="${knee_pitch_upper[leg_num-1]}" effort="${motorWheel_effort}" velocity="${motorWheel_velocity}"/> 
</joint>

</xacro:macro>
</robot>
