<?xml version="1.0"?>
<robot xmlns:xacro="http://ros.org/wiki/xacro">

<!-- macro legs -->
<xacro:macro name="wheel_leg" params="leg_num parent origin_x origin_y mirror">

<link name="knee_pitch_${leg_num}_link">
    <inertial>
        <origin xyz="${KneePitchWheel_x} ${KneePitchWheel_y} ${KneePitchWheel_z}"/>
        <mass value="${KneePitchWheel_mass}"/>
        <inertia ixx="${KneePitchWheel_xx}" ixy="${mirror*KneePitchWheel_xy}" ixz="${mirror*KneePitchWheel_xz}" iyy="${KneePitchWheel_yy}" iyz="${KneePitchWheel_yz}" izz="${KneePitchWheel_zz}"/>
    </inertial>
    <visual>
        <origin xyz="0.0 0.0 0.0"  rpy="0.0 0.0 0.0"/>
        <geometry>
            <mesh filename="package://kyon_urdf/meshes/mesh_fixed-wheel-leg.stl" scale="${mirror*0.001} 0.001 0.001"/>
        </geometry>
        <material name="dark_grey"/>
    </visual>
    <collision>
        <origin xyz="0.0 0.0 0.0"  rpy="0.0 0.0 0.0"/>
        <geometry>
            <mesh filename="package://kyon_urdf/meshes/collision/mesh_fixed-wheel-leg.stl" scale="${mirror*0.001} 0.001 0.001"/>
        </geometry>
    </collision>
</link>

<link name="wheel_${leg_num}_link">
    <inertial>
		<origin xyz="${Wheel_x} ${Wheel_y} ${Wheel_z}"/>
		<mass value="${Wheel_mass}"/>
		<inertia ixx="${Wheel_xx}" ixy="${Wheel_xy}" ixz="${Wheel_xz}" iyy="${Wheel_yy}" iyz="${Wheel_yz}" izz="${Wheel_zz}"/>
	</inertial>
	<visual>
		<origin xyz="0.0 0.0 0.0"  rpy="0.0 0.0 0.0"/>
	  	<geometry>
			<mesh filename="package://kyon_urdf/meshes/mesh_wheel.stl" scale="0.001 0.001 0.001"/>
		</geometry> 
  		<material name="dark_grey"/>
	</visual>
	<collision>
		<origin xyz="0.0 0.0 0.0"  rpy="0.0 0.0 0.0"/>
		<geometry>
			<mesh filename="package://kyon_urdf/meshes/collision/mesh_wheel.stl" scale="0.001 0.001 0.001"/>
		</geometry> 
	</collision>
</link>

<joint name="knee_pitch_${leg_num}" type="revolute">
    <parent link="${parent}"/>
    <child link="knee_pitch_${leg_num}_link"/>
    <origin xyz="${KneePitch_Ox} ${KneePitch_Oy} ${KneePitch_Oz}" rpy="${KneePitch_roll} ${KneePitch_pitch} ${KneePitch_yaw}"/>
    <axis xyz="0 0 1"/>
    <limit lower="${knee_pitch_lower[leg_num-1]}" upper="${knee_pitch_upper[leg_num-1]}" effort="${motorA_effort}" velocity="${motorA_velocity}"/> 
</joint>

<joint name="wheel_joint_${leg_num}" type="revolute">
    <parent link="knee_pitch_${leg_num}_link"/>
    <child link="wheel_${leg_num}_link"/>
    <origin xyz="${Wheel_Ox} ${Wheel_Oy} ${Wheel_Oz}" rpy="${Wheel_roll} ${Wheel_pitch} ${Wheel_yaw}"/>
    <axis xyz="0 0 1"/>
    <limit lower="${knee_pitch_lower[leg_num-1]}" upper="${knee_pitch_upper[leg_num-1]}" effort="${motorWheel_effort}" velocity="${motorWheel_velocity}"/> 
</joint>

</xacro:macro>
</robot>
